Workbook

Sheet How to use
A1: Kite Pulse — Keyword Research Sheet
A3: What this is | B3: Starter keyword list generated from 'Kite Pulse — Product Guide.md'. Every row has Source = Product guide.
A4: Step 1 | B4: Go to the Keywords tab. Fill in the YELLOW columns: Monthly Volume, Difficulty (KD), Trend (from Keyword Planner / Ahrefs / Semrush / Google Trends).
A5: Step 2 | B5: Check the Relevance score (1–3) that is pre-filled. Change it if you disagree.
A6: Step 3 | B6: The GREY columns calculate automatically: Intent Score, Difficulty Score, Priority. Do not type in them.
A7: Step 4 | B7: Search each Main keyword on Google and ask ChatGPT / Perplexity. Fill Currently Ranking, AI Cites and Content Gap / Angle.
A8: Step 5 | B8: Add new keywords you find (Google Autocomplete, People Also Ask, Reddit, competitors) as new rows. Copy the grey formulas down.
A9: Step 6 | B9: Use the AEO Tracking tab once a month to record whether AI assistants mention Kite Pulse.
A11: Colour key
A12: Yellow header / cell | B12: You fill this in
A13: Grey header / cell | B13: Formula — calculates automatically
A14: Blue text | B14: Pre-filled judgement you can change (e.g. Relevance)
A15: Priority colours | B15: Green = 8–9 (do first) · Amber = 6–7 (do next) · Red = 5 or below (later / drop)
A17: Scoring rules
A18: Relevance (1–3) | B18: 3 = Kite Pulse solves it directly · 2 = partly · 1 = loosely related
A19: Intent Score (1–3) | B19: Transactional = 3 · Commercial = 2 · Informational = 1 · Navigational = 1
A20: Difficulty Score (1–3) | B20: KD 0–20 = 3 (easy) · 21–50 = 2 (medium) · 51–100 = 1 (hard). Empty until you enter KD.
A21: Priority | B21: Relevance + Intent Score + Difficulty Score (max 9). Empty until KD is entered.
A23: Main / Secondary / FAQ | B23: Main = the page's one primary keyword (title, H1, URL). Secondary = used in subheadings and body. FAQ = AEO question answered in the page's FAQ section.
A24: Important | B24: Low or zero volume is normal for new AI-tool keywords. Do not delete a keyword only because volume is 0 if Relevance is 3.

Sheet Keywords
A1: ID | B1: Keyword / Question | C1: Type | D1: Source | E1: Keyword Group | F1: Monthly Volume | G1: Difficulty (KD) | H1: Trend | I1: Search Intent | J1: Relevance (1-3) | K1: Intent Score | L1: Difficulty Score | M1: Priority | N1: Main / Secondary | O1: Target Page URL | P1: Page Type | Q1: Currently Ranking (Google) | R1: AI Cites | S1: Content Gap / Angle | T1: Status | U1: Notes
A2: 1 | B2: ai coding analytics | C2: SEO | D2: Product guide | E2: Category | I2: Commercial | J2: 3 | K2: =IF(I2="","",IF(I2="Transactional",3,IF(I2="Commercial",2,1))) | L2: =IF(G2="","",IF(G2<=20,3,IF(G2<=50,2,1))) | M2: =IF(OR(J2="",K2="",L2=""),"",J2+K2+L2) | N2: Main | O2: / | P2: Home | Q2: Google checked 20 Oct 2026. Mixed results, no clear owner: 1. wakatime.com - product homepage (coding time tracking). Shows a homepage CAN rank for this keyword. 2. jellyfish.co - 'best AI coding analytics platforms' list written by a competitor. Shows searchers compare tools. 3. artificialanalysis.ai - different meaning: benchmarks of AI models, not developer analytics. Shows Google is unsure what the term means. 4. difinitydigital.com - paid ad (link has gclid), not an organic result; ignore. Kite Pulse does not rank yet. | S2: Gap: the category is new and nobody owns it; no result shows what AI coding analytics actually looks like for a team. Angle for the homepage (keep it a product page, not a guide): 1. Headline that defines the term: 'AI coding analytics: see how your team really uses AI coding assistants' - separates us from AI model benchmarks. 2. Clickable sample dashboard in the real console UI: usage per developer, cost per tool, plan-limit headroom, work patterns; filter by tool and project. 3. 'What would you see?': visitor picks their tools and team size, sample dashboard updates. 4. How it works animation: agent on each laptop, secrets stripped, data goes to your own server (answers privacy early). 5. Links to deep pages: /ai-cost-tracking, /claude-code-usage-limits, /ai-coding-assistant-pricing, /blog/ai-coding-roi. Off-page: get Kite Pulse onto neutral 'best AI coding analytics tools' lists - AI answer engines build answers from these lists. | T2: Not started | U2: Category to own
A3: 2 | B3: ai coding assistant analytics | C3: SEO | D3: Product guide | E3: Category | I3: Commercial | J3: 3 | K3: =IF(I3="","",IF(I3="Transactional",3,IF(I3="Commercial",2,1))) | L3: =IF(G3="","",IF(G3<=20,3,IF(G3<=50,2,1))) | M3: =IF(OR(J3="",K3="",L3=""),"",J3+K3+L3) | N3: Secondary | O3: / | P3: Home | Q3: Google checked 20 Oct 2026. Google mostly reads this as 'compare AI coding assistants', not 'analyse how your team uses them': 1. artificialanalysis.ai - benchmarks of coding agents (model/agent scores), not team usage analytics. 2. qodo.ai - 'best AI coding assistant tools' listicle by an assistant vendor. 3. axify.io - comparison of 20 AI coding assistants, written by an engineering-intelligence vendor (competitor). 4. jellyfish.co - 'best AI coding analytics platforms' list by a competitor. Only result that matches our meaning. Kite Pulse does not rank yet. Same domains as 'ai coding analytics' (jellyfish, artificialanalysis). | S3: Gap: 3 of 4 results compare assistants using generic benchmarks or vendor opinions; none lets a team compare assistants on its OWN usage data. Only jellyfish covers analytics, and it is a list, not a product view. Use on the homepage (Secondary to 'ai coding analytics'): 1. Use the phrase in a subheading, e.g. 'AI coding assistant analytics for your whole team'. 2. Homepage section that bridges the two meanings: 'Benchmarks tell you which assistant is best in general. Kite Pulse tells you which one works for your team.' 3. Sample dashboard view comparing tools side by side from real data: sessions, cost, retry loops, plan headroom per tool. Off-page: pitch Kite Pulse to 'best AI coding assistants' listicles (qodo/axify-style) as the way to evaluate them. | T3: Not started | U3: Moved to Secondary on the homepage 20 Oct 2026: Google results overlap with #1 'ai coding analytics' (jellyfish, artificialanalysis), so one page should target both.
A4: 3 | B4: ai coding analytics platform | C4: SEO | D4: Product guide | E4: Category | I4: Commercial | J4: 3 | K4: =IF(I4="","",IF(I4="Transactional",3,IF(I4="Commercial",2,1))) | L4: =IF(G4="","",IF(G4<=20,3,IF(G4<=50,2,1))) | M4: =IF(OR(J4="",K4="",L4=""),"",J4+K4+L4) | N4: Secondary | O4: /ai-coding-analytics | P4: Solution | T4: Not started
A5: 4 | B5: ai usage dashboard for developers | C5: SEO | D5: Product guide | E5: Category | I5: Commercial | J5: 3 | K5: =IF(I5="","",IF(I5="Transactional",3,IF(I5="Commercial",2,1))) | L5: =IF(G5="","",IF(G5<=20,3,IF(G5<=50,2,1))) | M5: =IF(OR(J5="",K5="",L5=""),"",J5+K5+L5) | N5: Secondary | O5: /ai-coding-analytics | P5: Solution | T5: Not started
A6: 5 | B6: ai adoption tracking | C6: SEO | D6: Product guide | E6: Category | I6: Commercial | J6: 3 | K6: =IF(I6="","",IF(I6="Transactional",3,IF(I6="Commercial",2,1))) | L6: =IF(G6="","",IF(G6<=20,3,IF(G6<=50,2,1))) | M6: =IF(OR(J6="",K6="",L6=""),"",J6+K6+L6) | N6: Secondary | O6: /ai-coding-analytics | P6: Solution | T6: Not started
A7: 6 | B7: track ai coding tool usage | C7: SEO | D7: Product guide | E7: Category | I7: Commercial | J7: 3 | K7: =IF(I7="","",IF(I7="Transactional",3,IF(I7="Commercial",2,1))) | L7: =IF(G7="","",IF(G7<=20,3,IF(G7<=50,2,1))) | M7: =IF(OR(J7="",K7="",L7=""),"",J7+K7+L7) | N7: Secondary | O7: /ai-coding-analytics | P7: Solution | T7: Not started
A8: 7 | B8: ai coding tools usage analytics for teams | C8: SEO | D8: Product guide | E8: Category | I8: Commercial | J8: 3 | K8: =IF(I8="","",IF(I8="Transactional",3,IF(I8="Commercial",2,1))) | L8: =IF(G8="","",IF(G8<=20,3,IF(G8<=50,2,1))) | M8: =IF(OR(J8="",K8="",L8=""),"",J8+K8+L8) | N8: Secondary | O8: /ai-coding-analytics | P8: Solution | T8: Not started
A9: 8 | B9: ai assisted development analytics | C9: SEO | D9: Product guide | E9: Category | I9: Commercial | J9: 3 | K9: =IF(I9="","",IF(I9="Transactional",3,IF(I9="Commercial",2,1))) | L9: =IF(G9="","",IF(G9<=20,3,IF(G9<=50,2,1))) | M9: =IF(OR(J9="",K9="",L9=""),"",J9+K9+L9) | N9: Secondary | O9: /ai-coding-analytics | P9: Solution | T9: Not started
A10: 9 | B10: engineering intelligence platform | C10: SEO | D10: Product guide | E10: Engineering Intelligence | I10: Commercial | J10: 2 | K10: =IF(I10="","",IF(I10="Transactional",3,IF(I10="Commercial",2,1))) | L10: =IF(G10="","",IF(G10<=20,3,IF(G10<=50,2,1))) | M10: =IF(OR(J10="",K10="",L10=""),"",J10+K10+L10) | N10: Main | O10: /engineering-intelligence | P10: Solution | Q10: Google checked 20 Oct 2026. Established category; Google shows explainers and comparisons, no product homepages: 1. cortex.io - 'engineering intelligence platforms: definition, benefits, tools'. Explainer + tool list: searchers first want to know what it is. 2. uplevelteam.com - 'top engineering intelligence platforms 2026'. Vendor-written 'best tools' list: searchers compare vendors. 3. spread.ai/platform - likely a different meaning: engineering intelligence for hardware / product engineering, not software teams (verify). 4. gartner.com - Peer Insights category 'Developer Productivity Insight Platforms'. Gartner's name for this market; a review site buyers trust. Kite Pulse does not rank yet. | S10: Gap: every vendor builds on outputs (commits, pull requests, tickets, surveys) and all ranking pages are text. Nobody covers engineering intelligence built on AI coding sessions (the work process), which is Kite Pulse's position in the product guide. Angle - solution page that explains and helps evaluate (not a blog, not a step-by-step guide): 1. Short answer defining the term for software teams (also separates us from Spread's hardware meaning). 2. 'Outputs vs process' animation: one feature as other platforms see it vs how Kite Pulse sees it. 3. 'Which platform fits us?' evaluator: questions to answer + data available -> scored checklist; honest about when a git/Jira-based tool fits better (e.g. DORA, cycle time). 4. Platform-type comparison table linking to /compare pages. 5. Clickable sample dashboard. 6. FAQ from the AEO questions mapped to this page. | T10: Not started | U10: Competitive. Earlier note said LinearB and Jellyfish rank here; Google check on 20 Oct 2026 showed Cortex, Uplevel, Spread (different meaning) and Gartner Peer Insights instead
A11: 10 | B11: software engineering intelligence | C11: SEO | D11: Product guide | E11: Engineering Intelligence | I11: Commercial | J11: 2 | K11: =IF(I11="","",IF(I11="Transactional",3,IF(I11="Commercial",2,1))) | L11: =IF(G11="","",IF(G11<=20,3,IF(G11<=50,2,1))) | M11: =IF(OR(J11="",K11="",L11=""),"",J11+K11+L11) | N11: Secondary | O11: /engineering-intelligence | P11: Solution | T11: Not started
A12: 11 | B12: developer productivity tool | C12: SEO | D12: Product guide | E12: Engineering Intelligence | I12: Commercial | J12: 2 | K12: =IF(I12="","",IF(I12="Transactional",3,IF(I12="Commercial",2,1))) | L12: =IF(G12="","",IF(G12<=20,3,IF(G12<=50,2,1))) | M12: =IF(OR(J12="",K12="",L12=""),"",J12+K12+L12) | N12: Secondary | O12: /engineering-intelligence | P12: Solution | T12: Not started
A13: 12 | B13: developer analytics | C13: SEO | D13: Product guide | E13: Engineering Intelligence | I13: Commercial | J13: 2 | K13: =IF(I13="","",IF(I13="Transactional",3,IF(I13="Commercial",2,1))) | L13: =IF(G13="","",IF(G13<=20,3,IF(G13<=50,2,1))) | M13: =IF(OR(J13="",K13="",L13=""),"",J13+K13+L13) | N13: Secondary | O13: /engineering-intelligence | P13: Solution | T13: Not started
A14: 13 | B14: developer productivity analytics | C14: SEO | D14: Product guide | E14: Engineering Intelligence | I14: Commercial | J14: 2 | K14: =IF(I14="","",IF(I14="Transactional",3,IF(I14="Commercial",2,1))) | L14: =IF(G14="","",IF(G14<=20,3,IF(G14<=50,2,1))) | M14: =IF(OR(J14="",K14="",L14=""),"",J14+K14+L14) | N14: Secondary | O14: /engineering-intelligence | P14: Solution | T14: Not started
A15: 14 | B15: engineering visibility tool | C15: SEO | D15: Product guide | E15: Engineering Intelligence | I15: Commercial | J15: 3 | K15: =IF(I15="","",IF(I15="Transactional",3,IF(I15="Commercial",2,1))) | L15: =IF(G15="","",IF(G15<=20,3,IF(G15<=50,2,1))) | M15: =IF(OR(J15="",K15="",L15=""),"",J15+K15+L15) | N15: Secondary | O15: /engineering-intelligence | P15: Solution | T15: Not started
A16: 15 | B16: developer experience metrics | C16: SEO | D16: Product guide | E16: Engineering Intelligence | I16: Informational | J16: 2 | K16: =IF(I16="","",IF(I16="Transactional",3,IF(I16="Commercial",2,1))) | L16: =IF(G16="","",IF(G16<=20,3,IF(G16<=50,2,1))) | M16: =IF(OR(J16="",K16="",L16=""),"",J16+K16+L16) | N16: Main | O16: /blog/developer-experience-metrics | P16: Interactive guide | Q16: Google checked 20 Oct 2026. All results teach; no product pages rank: 1. getdx.com - 'developer productivity metrics' blog. DX is the company behind the best-known DevEx framework. 2. cortex.io - 'developer experience metrics' blog. 3. port.io - 'DevEx metrics: best practices, key components and examples' blog. 4. github.com/inDriver/handbook - a real company's internal DevEx metrics framework, published openly. Shows Google rewards a framework a team can actually use. 5. mstone.ai - glossary entry 'Developer Experience Index'. Shows short, quotable definitions rank (and feed AI answers). Kite Pulse does not rank yet. | S16: Gap: all results are text, and the common frameworks (SPACE, DevEx framework, DX Core 4) lean on surveys. Nobody lets the reader build their own metric set, and nobody covers what AI coding sessions now show directly. Angle - 'DevEx metrics for the AI era: what surveys measure and what AI sessions now show directly' (honest that surveys still matter for how developers feel): 1. Short answer + one-line definitions of key terms (competes with the glossary result). 2. Framework explorer: tabs for SPACE, DevEx framework, DX Core 4 with dimensions and example metrics. 3. Metric library (~30 metrics) filterable by dimension, data source (survey / system / AI sessions) and effort. 4. 'Build your DevEx scorecard': pick 5-8 metrics, get targets and how to measure each, copy it (the practical framework that made the GitHub handbook rank). 5. AI-era signals: retries, abandoned approaches, stuck sessions, error loops, with a session animation - Kite Pulse comes in here. 6. 6-question team pulse check, labelled as a self-check, not a benchmark. 7. FAQ. | T16: Not started
A17: 16 | B17: measure developer experience without surveys | C17: SEO | D17: Product guide | E17: Engineering Intelligence | I17: Informational | J17: 3 | K17: =IF(I17="","",IF(I17="Transactional",3,IF(I17="Commercial",2,1))) | L17: =IF(G17="","",IF(G17<=20,3,IF(G17<=50,2,1))) | M17: =IF(OR(J17="",K17="",L17=""),"",J17+K17+L17) | N17: Secondary | O17: /blog/developer-experience-metrics | P17: Interactive guide | T17: Not started
A18: 17 | B18: measure developer productivity with ai | C18: SEO | D18: Product guide | E18: Engineering Intelligence | I18: Informational | J18: 2 | K18: =IF(I18="","",IF(I18="Transactional",3,IF(I18="Commercial",2,1))) | L18: =IF(G18="","",IF(G18<=20,3,IF(G18<=50,2,1))) | M18: =IF(OR(J18="",K18="",L18=""),"",J18+K18+L18) | N18: Main | O18: /blog/measure-developer-productivity-ai | P18: Interactive guide | Q18: Google checked 20 Oct 2026. All text; mix of vendor method content and developer scepticism: 1. getdx.com - 'AI measurement hub'. Vendor resource hub with a framework for measuring AI impact: searchers want a structured method. 2. Reddit r/programming - 'Measuring the impact of AI on experienced ... developer productivity'. Developers discussing a study, probably METR (2025), which found experienced developers were slower with AI while believing they were faster: searchers are sceptical and want evidence, not vendor claims. 3. axify.io - 'use AI for developer productivity'. About using AI to be more productive - a slightly different intent. 4. uplevelteam.com - 'measuring developer productivity'. General measurement guide. Kite Pulse does not rank yet. | S18: Gap: nobody lets readers test their assumptions or design a fair measurement, and vendor pages repeat speed-up claims the Reddit audience does not trust. Angle - evidence over hype: 'Output counts cannot tell you if AI is helping; here is how to measure it properly, including the process inside AI sessions' (product guide: more commits and PRs, yet delivery feels no faster). 1. Short answer. 2. 'Guess first' game: reader guesses AI speed-up, then sees the research with a link (verify study figures against the paper). 3. 'Good metric or vanity metric?' quiz (AI lines of code, acceptance rate, commits, cycle time, change failure rate, rework). 4. Framework explorer: adoption, delivery, quality, experience. 5. 'Design a fair test' builder: team, baseline, comparison group, 3 metrics -> copyable plan. 6. What AI sessions reveal (retries, abandoned approaches) - Kite Pulse comes in here. 7. FAQ. Later: anonymised, aggregated Kite Pulse data report (needs customer consent and privacy review). | T18: Not started
A19: 18 | B19: ai coding cost tracking | C19: SEO | D19: Product guide | E19: Cost | I19: Commercial | J19: 3 | K19: =IF(I19="","",IF(I19="Transactional",3,IF(I19="Commercial",2,1))) | L19: =IF(G19="","",IF(G19<=20,3,IF(G19<=50,2,1))) | M19: =IF(OR(J19="",K19="",L19=""),"",J19+K19+L19) | N19: Main | O19: /ai-cost-tracking | P19: Interactive guide | Q19: How-to guides from AI coding / engineering intelligence vendors (Larridin, Faros AI). Checked 20 Oct 2026 | S19: Competitors are text guides. Ours: interactive guide with calculators, a waste-spotting quiz and a generated tracking plan; Kite Pulse shown where it saves effort | T19: Not started
A20: 19 | B20: ai cost tracking | C20: SEO | D20: Product guide | E20: Cost | I20: Commercial | J20: 2 | K20: =IF(I20="","",IF(I20="Transactional",3,IF(I20="Commercial",2,1))) | L20: =IF(G20="","",IF(G20<=20,3,IF(G20<=50,2,1))) | M20: =IF(OR(J20="",K20="",L20=""),"",J20+K20+L20) | N20: Secondary | O20: /ai-cost-tracking | P20: Interactive guide | T20: Not started | U20: Broad; may bring API-billing searchers
A21: 20 | B21: ai spend management | C21: SEO | D21: Product guide | E21: Cost | I21: Commercial | J21: 2 | K21: =IF(I21="","",IF(I21="Transactional",3,IF(I21="Commercial",2,1))) | L21: =IF(G21="","",IF(G21<=20,3,IF(G21<=50,2,1))) | M21: =IF(OR(J21="",K21="",L21=""),"",J21+K21+L21) | N21: Secondary | O21: /ai-cost-tracking | P21: Interactive guide | T21: Not started
A22: 21 | B22: ai tool spend per developer | C22: SEO | D22: Product guide | E22: Cost | I22: Commercial | J22: 3 | K22: =IF(I22="","",IF(I22="Transactional",3,IF(I22="Commercial",2,1))) | L22: =IF(G22="","",IF(G22<=20,3,IF(G22<=50,2,1))) | M22: =IF(OR(J22="",K22="",L22=""),"",J22+K22+L22) | N22: Secondary | O22: /ai-cost-tracking | P22: Interactive guide | T22: Not started
A23: 22 | B23: ai coding cost per developer | C23: SEO | D23: Product guide | E23: Cost | I23: Commercial | J23: 3 | K23: =IF(I23="","",IF(I23="Transactional",3,IF(I23="Commercial",2,1))) | L23: =IF(G23="","",IF(G23<=20,3,IF(G23<=50,2,1))) | M23: =IF(OR(J23="",K23="",L23=""),"",J23+K23+L23) | N23: Secondary | O23: /ai-cost-tracking | P23: Interactive guide | T23: Not started
A24: 23 | B24: ai cost per project | C24: SEO | D24: Product guide | E24: Cost | I24: Commercial | J24: 3 | K24: =IF(I24="","",IF(I24="Transactional",3,IF(I24="Commercial",2,1))) | L24: =IF(G24="","",IF(G24<=20,3,IF(G24<=50,2,1))) | M24: =IF(OR(J24="",K24="",L24=""),"",J24+K24+L24) | N24: Secondary | O24: /ai-cost-tracking | P24: Interactive guide | T24: Not started
A25: 24 | B25: token usage monitoring | C25: SEO | D25: Product guide | E25: Cost | I25: Commercial | J25: 3 | K25: =IF(I25="","",IF(I25="Transactional",3,IF(I25="Commercial",2,1))) | L25: =IF(G25="","",IF(G25<=20,3,IF(G25<=50,2,1))) | M25: =IF(OR(J25="",K25="",L25=""),"",J25+K25+L25) | N25: Secondary | O25: /ai-cost-tracking | P25: Interactive guide | T25: Not started
A26: 25 | B26: token usage per developer | C26: SEO | D26: Product guide | E26: Cost | I26: Commercial | J26: 3 | K26: =IF(I26="","",IF(I26="Transactional",3,IF(I26="Commercial",2,1))) | L26: =IF(G26="","",IF(G26<=20,3,IF(G26<=50,2,1))) | M26: =IF(OR(J26="",K26="",L26=""),"",J26+K26+L26) | N26: Secondary | O26: /ai-cost-tracking | P26: Interactive guide | T26: Not started
A27: 26 | B27: track llm token usage by team | C27: SEO | D27: Product guide | E27: Cost | I27: Commercial | J27: 3 | K27: =IF(I27="","",IF(I27="Transactional",3,IF(I27="Commercial",2,1))) | L27: =IF(G27="","",IF(G27<=20,3,IF(G27<=50,2,1))) | M27: =IF(OR(J27="",K27="",L27=""),"",J27+K27+L27) | N27: Secondary | O27: /ai-cost-tracking | P27: Interactive guide | T27: Not started
A28: 27 | B28: measure roi of ai coding tools | C28: SEO | D28: Product guide | E28: Cost | I28: Informational | J28: 2 | K28: =IF(I28="","",IF(I28="Transactional",3,IF(I28="Commercial",2,1))) | L28: =IF(G28="","",IF(G28<=20,3,IF(G28<=50,2,1))) | M28: =IF(OR(J28="",K28="",L28=""),"",J28+K28+L28) | N28: Main | O28: /blog/ai-coding-roi | P28: Interactive guide | Q28: 1 getdx.com (ROI calculator) · 2 LinkedIn article (Mamoon Chowdry) · 3 ibm.com (case study) · 4 jellyfish.co · 5 pensero.ai. Checked 20 Oct 2026 | S28: #1 is a calculator, the rest are measurement frameworks. Ours: interactive guide + ROI calculator with shareable inputs; replace guessed inputs with measured cost and usage | T28: Not started | U28: Cost & ROI page is switched off; link to /ai-cost-tracking
A29: 28 | B29: ai coding roi | C29: SEO | D29: Product guide | E29: Cost | I29: Informational | J29: 2 | K29: =IF(I29="","",IF(I29="Transactional",3,IF(I29="Commercial",2,1))) | L29: =IF(G29="","",IF(G29<=20,3,IF(G29<=50,2,1))) | M29: =IF(OR(J29="",K29="",L29=""),"",J29+K29+L29) | N29: Secondary | O29: /blog/ai-coding-roi | P29: Interactive guide | T29: Not started
A30: 29 | B30: claude code usage limits | C30: SEO | D30: Product guide | E30: Limits | I30: Informational | J30: 3 | K30: =IF(I30="","",IF(I30="Transactional",3,IF(I30="Commercial",2,1))) | L30: =IF(G30="","",IF(G30<=20,3,IF(G30<=50,2,1))) | M30: =IF(OR(J30="",K30="",L30=""),"",J30+K30+L30) | N30: Main | O30: /claude-code-usage-limits | P30: Interactive guide | Q30: 1 support.claude.com (official article) · 2 truefoundry.com (blog) · 3 Reddit r/ClaudeCode (user story) · 4 fast.io (guide) · 5 claudelog.com. All text. Checked 20 Oct 2026 | S30: Results explain the rules but none show what your own usage means. Ours: plan picker, reset-window timeline, 'what uses your limit fastest' meter, limit simulator, 'hit my limit' decision tree, tips with real Reddit/HN quotes; team view links to /plan-headroom | T30: Not started
A31: 30 | B31: claude usage limit | C31: SEO | D31: Product guide | E31: Limits | I31: Informational | J31: 2 | K31: =IF(I31="","",IF(I31="Transactional",3,IF(I31="Commercial",2,1))) | L31: =IF(G31="","",IF(G31<=20,3,IF(G31<=50,2,1))) | M31: =IF(OR(J31="",K31="",L31=""),"",J31+K31+L31) | N31: Secondary | O31: /claude-code-usage-limits | P31: Interactive guide | T31: Not started
A32: 31 | B32: claude weekly limit | C32: SEO | D32: Product guide | E32: Limits | I32: Informational | J32: 2 | K32: =IF(I32="","",IF(I32="Transactional",3,IF(I32="Commercial",2,1))) | L32: =IF(G32="","",IF(G32<=20,3,IF(G32<=50,2,1))) | M32: =IF(OR(J32="",K32="",L32=""),"",J32+K32+L32) | N32: Secondary | O32: /claude-code-usage-limits | P32: Interactive guide | T32: Not started
A33: 32 | B33: claude 5 hour limit | C33: SEO | D33: Product guide | E33: Limits | I33: Informational | J33: 2 | K33: =IF(I33="","",IF(I33="Transactional",3,IF(I33="Commercial",2,1))) | L33: =IF(G33="","",IF(G33<=20,3,IF(G33<=50,2,1))) | M33: =IF(OR(J33="",K33="",L33=""),"",J33+K33+L33) | N33: Secondary | O33: /claude-code-usage-limits | P33: Interactive guide | T33: Not started
A34: 33 | B34: avoid hitting claude limit | C34: SEO | D34: Product guide | E34: Limits | I34: Informational | J34: 3 | K34: =IF(I34="","",IF(I34="Transactional",3,IF(I34="Commercial",2,1))) | L34: =IF(G34="","",IF(G34<=20,3,IF(G34<=50,2,1))) | M34: =IF(OR(J34="",K34="",L34=""),"",J34+K34+L34) | N34: Secondary | O34: /claude-code-usage-limits | P34: Interactive guide | T34: Not started
A35: 34 | B35: claude code rate limits team | C35: SEO | D35: Product guide | E35: Limits | I35: Commercial | J35: 3 | K35: =IF(I35="","",IF(I35="Transactional",3,IF(I35="Commercial",2,1))) | L35: =IF(G35="","",IF(G35<=20,3,IF(G35<=50,2,1))) | M35: =IF(OR(J35="",K35="",L35=""),"",J35+K35+L35) | N35: Secondary | O35: /plan-headroom | P35: Feature | T35: Not started
A36: 35 | B36: monitor claude plan usage team | C36: SEO | D36: Product guide | E36: Limits | I36: Commercial | J36: 3 | K36: =IF(I36="","",IF(I36="Transactional",3,IF(I36="Commercial",2,1))) | L36: =IF(G36="","",IF(G36<=20,3,IF(G36<=50,2,1))) | M36: =IF(OR(J36="",K36="",L36=""),"",J36+K36+L36) | N36: Secondary | O36: /plan-headroom | P36: Feature | T36: Not started
A37: 36 | B37: ai plan limits | C37: SEO | D37: Product guide | E37: Limits | I37: Informational | J37: 2 | K37: =IF(I37="","",IF(I37="Transactional",3,IF(I37="Commercial",2,1))) | L37: =IF(G37="","",IF(G37<=20,3,IF(G37<=50,2,1))) | M37: =IF(OR(J37="",K37="",L37=""),"",J37+K37+L37) | N37: Secondary | O37: /plan-headroom | P37: Feature | T37: Not started
A38: 37 | B38: shadow ai coding tools | C38: SEO | D38: Product guide | E38: Shadow AI & Seats | I38: Commercial | J38: 3 | K38: =IF(I38="","",IF(I38="Transactional",3,IF(I38="Commercial",2,1))) | L38: =IF(G38="","",IF(G38<=20,3,IF(G38<=50,2,1))) | M38: =IF(OR(J38="",K38="",L38=""),"",J38+K38+L38) | N38: Main | O38: /shadow-ai | P38: Solution | T38: Not started
A39: 38 | B39: shadow ai | C39: SEO | D39: Product guide | E39: Shadow AI & Seats | I39: Informational | J39: 2 | K39: =IF(I39="","",IF(I39="Transactional",3,IF(I39="Commercial",2,1))) | L39: =IF(G39="","",IF(G39<=20,3,IF(G39<=50,2,1))) | M39: =IF(OR(J39="",K39="",L39=""),"",J39+K39+L39) | N39: Secondary | O39: /shadow-ai | P39: Solution | T39: Not started | U39: Hard; security vendors rank
A40: 39 | B40: detect ai tools used by developers | C40: SEO | D40: Product guide | E40: Shadow AI & Seats | I40: Commercial | J40: 3 | K40: =IF(I40="","",IF(I40="Transactional",3,IF(I40="Commercial",2,1))) | L40: =IF(G40="","",IF(G40<=20,3,IF(G40<=50,2,1))) | M40: =IF(OR(J40="",K40="",L40=""),"",J40+K40+L40) | N40: Secondary | O40: /shadow-ai | P40: Solution | T40: Not started
...

Sheet Page Map
A1: Page URL | B1: Page Type | C1: Main Keyword | D1: No. of Keywords | E1: No. of AEO Questions | F1: Priority (P1/P2/P3) | G1: Status | H1: Publish Date | I1: Notes
A2: / | B2: Home | C2: ai coding analytics | D2: =COUNTIFS(Keywords!$O:$O,A2,Keywords!$C:$C,"SEO") | E2: =COUNTIFS(Keywords!$O:$O,A2,Keywords!$C:$C,"AEO") | F2: P1 | G2: Not started | I2: Main keyword 'ai coding analytics' (Google checked 20 Oct 2026): WakaTime's homepage ranks #1, so a product homepage is the right format here - no guide needed. Results are mixed (product page, a competitor's tools list, AI model benchmarks), so the category has no owner yet. Make the homepage interactive with a live sample dashboard, not long text: - Headline defines the term (team use of AI coding assistants, not model benchmarks). - Clickable sample dashboard: usage per developer, cost per tool, plan-limit headroom, work patterns; filters by tool and project. - 'What would you see?' picker: tools + team size update the sample dashboard. - Short 'how it works' animation with the privacy story (secrets stripped, own server). - Links to /ai-cost-tracking, /claude-code-usage-limits, /ai-coding-assistant-pricing, /blog/ai-coding-roi. Also: pitch neutral review sites and newsletters to list Kite Pulse in 'best AI coding analytics tools' lists; build /compare pages (Competitors tab).
A3: /ai-coding-analytics | B3: Solution | C3: TBD - needs new main keyword | D3: =COUNTIFS(Keywords!$O:$O,A3,Keywords!$C:$C,"SEO") | E3: =COUNTIFS(Keywords!$O:$O,A3,Keywords!$C:$C,"AEO") | F3: P2 | G3: Not started | I3: 20 Oct 2026: 'ai coding assistant analytics' gave the same kind of results as the homepage keyword, so it moved to the homepage as Secondary. This page needs a new main keyword from its remaining cluster (team AI usage / adoption tracking), e.g. 'ai adoption tracking', 'track ai coding tool usage' or 'ai coding tool usage analytics'. Search the candidates on Google and pick the one whose results differ from the homepage's.
A4: /engineering-intelligence | B4: Solution | C4: engineering intelligence platform | D4: =COUNTIFS(Keywords!$O:$O,A4,Keywords!$C:$C,"SEO") | E4: =COUNTIFS(Keywords!$O:$O,A4,Keywords!$C:$C,"AEO") | F4: P2 | G4: Not started | I4: Solution page that defines the category and helps buyers evaluate - not a blog (dated, outside product pages) and not a step-by-step guide (no method to teach). Google (20 Oct 2026) shows explainers and 'top platforms' lists (Cortex, Uplevel), a different meaning (Spread, hardware engineering) and Gartner Peer Insights ('Developer Productivity Insight Platforms'); no product homepage ranks. Core message: the engineering intelligence platform built on AI coding sessions (the process), not commits, tickets and surveys (the outputs). Interactive parts: short answer definition; 'outputs vs process' animation; 'Which platform fits us?' evaluator (questions + data sources -> scored checklist, honest about when git/Jira tools fit better, e.g. DORA, cycle time); platform-type comparison table linking to /compare pages; clickable sample dashboard; FAQ from mapped AEO questions. Off-page: list Kite Pulse on Gartner Peer Insights and collect reviews; pitch neutral 'top platforms' list writers. Secondary keyword added: 'developer productivity insight platform' (Gartner's term).
A5: /blog/developer-experience-metrics | B5: Interactive guide | C5: developer experience metrics | D5: =COUNTIFS(Keywords!$O:$O,A5,Keywords!$C:$C,"SEO") | E5: =COUNTIFS(Keywords!$O:$O,A5,Keywords!$C:$C,"AEO") | F5: P3 | G5: Not started | I5: Interactive guide: searchers want to learn which metrics to use and how to measure them. Google (20 Oct 2026) shows only educational pages: vendor blogs (DX, Cortex, Port), a company handbook on GitHub (inDriver) and a glossary entry (mstone.ai); all text. Core angle: DevEx metrics for the AI era - surveys measure how developers feel; Kite Pulse shows friction directly in retries, failures and long sessions, with no survey. Interactive parts: short answer + definitions; framework explorer (SPACE, DevEx framework, DX Core 4); filterable metric library; 'Build your DevEx scorecard' (copyable); AI-era signals with session animation; 6-question team pulse check; FAQ. URL stays in /blog: DevEx frameworks change slowly, unlike pricing and plan limits; review now and then. Priority stays P3: DX and Cortex are strong here and this page supports the main product pages.
A6: /blog/measure-developer-productivity-ai | B6: Interactive guide | C6: measure developer productivity with ai | D6: =COUNTIFS(Keywords!$O:$O,A6,Keywords!$C:$C,"SEO") | E6: =COUNTIFS(Keywords!$O:$O,A6,Keywords!$C:$C,"AEO") | F6: P3 | G6: Not started | I6: Interactive guide: searchers want a proper method to measure AI's effect on productivity. Google (20 Oct 2026): DX 'AI measurement hub', a Reddit debate about a study (probably METR 2025) showing experienced developers were slower with AI, Axify and Uplevel blogs; all text. Core angle: evidence over hype - output counts cannot show if AI helps; measure properly, including the process inside AI sessions. Interactive parts: 'guess first' speed-up game with real research; 'good metric or vanity metric?' quiz; framework explorer (adoption, delivery, quality, experience); 'design a fair test' builder with copyable plan; AI-session animation (retries, abandoned approaches) where Kite Pulse comes in; FAQ. Later: anonymised Kite Pulse data report (consent + privacy review first). Separate jobs, cross-link: this page = is AI making us faster and better; /blog/ai-coding-roi = is it worth the money; /blog/developer-experience-metrics = how the work feels; /engineering-intelligence = which platform to buy. DX ranks for both this and the ROI keyword, so keep ROI about money. URL stays in /blog; priority stays P3. Note: 'tokenmaxxing' rows also target this page as a second Main keyword - decide if it needs its own page.
A7: /ai-cost-tracking | B7: Interactive guide | C7: ai coding cost tracking | D7: =COUNTIFS(Keywords!$O:$O,A7,Keywords!$C:$C,"SEO") | E7: =COUNTIFS(Keywords!$O:$O,A7,Keywords!$C:$C,"AEO") | F7: P2 | G7: Not started | I7: Interactive guide, not a sales page or text blog. Google shows how-to guides (Larridin, Faros AI). 9 hands-on steps: setup, tokens to dollars, cost estimate, tracking methods, split by project, waste quiz, billable view, generated plan. Prototype: https://claude.ai/artifact/MW9gPq11m5pA4ULoAoiBec. Link to pricing and ROI pages
A8: /blog/ai-coding-roi | B8: Interactive guide | C8: measure roi of ai coding tools | D8: =COUNTIFS(Keywords!$O:$O,A8,Keywords!$C:$C,"SEO") | E8: =COUNTIFS(Keywords!$O:$O,A8,Keywords!$C:$C,"AEO") | F8: P3 | G8: Not started | I8: Interactive guide + ROI calculator. Google #1 is DX's ROI calculator; others are measurement frameworks (IBM, Jellyfish, Pensero). Put calculator inputs in the URL so results can be shared. Only claim measured cost and usage: Cost & ROI page is switched off. Link to /ai-cost-tracking
A9: /claude-code-usage-limits | B9: Interactive guide | C9: claude code usage limits | D9: =COUNTIFS(Keywords!$O:$O,A9,Keywords!$C:$C,"SEO") | E9: =COUNTIFS(Keywords!$O:$O,A9,Keywords!$C:$C,"AEO") | F9: P3 | G9: Not started | I9: Interactive guide, not a text blog; permanent URL outside /blog because limits change. Google shows the official support article, explainer blogs and a Reddit user story. Steps: short answer, pick your plan, how the reset window works, what uses your limit fastest, limit simulator, 'I hit my limit' decision tree, habits checklist, team view (link to /plan-headroom), FAQ. Keep plan rules in one data file with source link and 'checked' date; check monthly. No invented limit numbers
A10: /plan-headroom | B10: Feature | C10: claude code rate limits team | D10: =COUNTIFS(Keywords!$O:$O,A10,Keywords!$C:$C,"SEO") | E10: =COUNTIFS(Keywords!$O:$O,A10,Keywords!$C:$C,"AEO") | F10: P2 | G10: Not started
A11: /shadow-ai | B11: Solution | C11: shadow ai coding tools | D11: =COUNTIFS(Keywords!$O:$O,A11,Keywords!$C:$C,"SEO") | E11: =COUNTIFS(Keywords!$O:$O,A11,Keywords!$C:$C,"AEO") | F11: P2 | G11: Not started
A12: /blog/secrets-in-ai-prompts | B12: Blog | C12: secrets in ai coding prompts | D12: =COUNTIFS(Keywords!$O:$O,A12,Keywords!$C:$C,"SEO") | E12: =COUNTIFS(Keywords!$O:$O,A12,Keywords!$C:$C,"AEO") | F12: P3 | G12: Not started
A13: /self-hosted | B13: Trust | C13: self-hosted developer analytics | D13: =COUNTIFS(Keywords!$O:$O,A13,Keywords!$C:$C,"SEO") | E13: =COUNTIFS(Keywords!$O:$O,A13,Keywords!$C:$C,"AEO") | F13: P1 | G13: Not started
A14: /privacy | B14: Trust | C14: privacy-first developer analytics | D14: =COUNTIFS(Keywords!$O:$O,A14,Keywords!$C:$C,"SEO") | E14: =COUNTIFS(Keywords!$O:$O,A14,Keywords!$C:$C,"AEO") | F14: P1 | G14: Not started
A15: /features | B15: Feature | C15: team activity dashboard | D15: =COUNTIFS(Keywords!$O:$O,A15,Keywords!$C:$C,"SEO") | E15: =COUNTIFS(Keywords!$O:$O,A15,Keywords!$C:$C,"AEO") | F15: P1 | G15: Not started
A16: /blog/engineering-burnout-signals | B16: Blog | C16: engineering burnout early warning | D16: =COUNTIFS(Keywords!$O:$O,A16,Keywords!$C:$C,"SEO") | E16: =COUNTIFS(Keywords!$O:$O,A16,Keywords!$C:$C,"AEO") | F16: P3 | G16: Not started
A17: /blog/ai-retry-loops | B17: Blog | C17: ai retry loops developers | D17: =COUNTIFS(Keywords!$O:$O,A17,Keywords!$C:$C,"SEO") | E17: =COUNTIFS(Keywords!$O:$O,A17,Keywords!$C:$C,"AEO") | F17: P3 | G17: Not started
A18: /blog/institutional-knowledge | B18: Blog | C18: institutional knowledge software teams | D18: =COUNTIFS(Keywords!$O:$O,A18,Keywords!$C:$C,"SEO") | E18: =COUNTIFS(Keywords!$O:$O,A18,Keywords!$C:$C,"AEO") | F18: P3 | G18: Not started
A19: /docs | B19: Docs | C19: mcp server developer analytics | D19: =COUNTIFS(Keywords!$O:$O,A19,Keywords!$C:$C,"SEO") | E19: =COUNTIFS(Keywords!$O:$O,A19,Keywords!$C:$C,"AEO") | F19: P2 | G19: Not started
A20: /blog/ai-weekly-team-report | B20: Blog | C20: ai assistant weekly team report | D20: =COUNTIFS(Keywords!$O:$O,A20,Keywords!$C:$C,"SEO") | E20: =COUNTIFS(Keywords!$O:$O,A20,Keywords!$C:$C,"AEO") | F20: P3 | G20: Not started
A21: /blog/agentic-coding | B21: Blog | C21: agentic coding | D21: =COUNTIFS(Keywords!$O:$O,A21,Keywords!$C:$C,"SEO") | E21: =COUNTIFS(Keywords!$O:$O,A21,Keywords!$C:$C,"AEO") | F21: P3 | G21: Not started
... A34: /blog/claude-code-vs-cursor | B34: Blog | C34: claude code vs cursor usage | D34: =COUNTIFS(Keywords!$O:$O,A34,Keywords!$C:$C,"SEO") | E34: =COUNTIFS(Keywords!$O:$O,A34,Keywords!$C:$C,"AEO") | F34: P3 | G34: Not started
A35: /faq | B35: FAQ | D35: =COUNTIFS(Keywords!$O:$O,A35,Keywords!$C:$C,"SEO") | E35: =COUNTIFS(Keywords!$O:$O,A35,Keywords!$C:$C,"AEO") | F35: P1 | G35: Not started
A36: /pricing | B36: Solution | D36: =COUNTIFS(Keywords!$O:$O,A36,Keywords!$C:$C,"SEO") | E36: =COUNTIFS(Keywords!$O:$O,A36,Keywords!$C:$C,"AEO") | F36: P1 | G36: Not started | I36: Supporting page; no target keyword needed
A37: /about | B37: Solution | D37: =COUNTIFS(Keywords!$O:$O,A37,Keywords!$C:$C,"SEO") | E37: =COUNTIFS(Keywords!$O:$O,A37,Keywords!$C:$C,"AEO") | F37: P2 | G37: Not started | I37: Supporting page; no target keyword needed
A38: /compare/linearb | B38: Compare | C38: linearb alternatives | D38: =COUNTIFS(Keywords!$O:$O,A38,Keywords!$C:$C,"SEO") | E38: =COUNTIFS(Keywords!$O:$O,A38,Keywords!$C:$C,"AEO") | F38: P3 | G38: Not started | I38: Add competitor keywords (e.g. '<name> alternative') from Ahrefs/Semrush
A39: /compare/jellyfish | B39: Compare | D39: =COUNTIFS(Keywords!$O:$O,A39,Keywords!$C:$C,"SEO") | E39: =COUNTIFS(Keywords!$O:$O,A39,Keywords!$C:$C,"AEO") | F39: P3 | G39: Not started | I39: Add competitor keywords (e.g. '<name> alternative') from Ahrefs/Semrush
A40: /compare/dx | B40: Compare | C40: getdx alternatives | D40: =COUNTIFS(Keywords!$O:$O,A40,Keywords!$C:$C,"SEO") | E40: =COUNTIFS(Keywords!$O:$O,A40,Keywords!$C:$C,"AEO") | F40: P3 | G40: Not started | I40: Add competitor keywords (e.g. '<name> alternative') from Ahrefs/Semrush
A41: /compare/swarmia | B41: Compare | D41: =COUNTIFS(Keywords!$O:$O,A41,Keywords!$C:$C,"SEO") | E41: =COUNTIFS(Keywords!$O:$O,A41,Keywords!$C:$C,"AEO") | F41: P3 | G41: Not started | I41: Add competitor keywords (e.g. '<name> alternative') from Ahrefs/Semrush
A42: /compare/github-copilot-metrics | B42: Compare | C42: copilot metrics viewer | D42: =COUNTIFS(Keywords!$O:$O,A42,Keywords!$C:$C,"SEO") | E42: =COUNTIFS(Keywords!$O:$O,A42,Keywords!$C:$C,"AEO") | F42: P3 | G42: Not started | I42: Add competitor keywords (e.g. '<name> alternative') from Ahrefs/Semrush
A43: /compare/anthropic-console | B43: Compare | D43: =COUNTIFS(Keywords!$O:$O,A43,Keywords!$C:$C,"SEO") | E43: =COUNTIFS(Keywords!$O:$O,A43,Keywords!$C:$C,"AEO") | F43: P3 | G43: Not started | I43: Add competitor keywords (e.g. '<name> alternative') from Ahrefs/Semrush
A44: /blog | B44: Blog | D44: =COUNTIFS(Keywords!$O:$O,A44,Keywords!$C:$C,"SEO") | E44: =COUNTIFS(Keywords!$O:$O,A44,Keywords!$C:$C,"AEO") | F44: P3 | G44: Not started | I44: Supporting page; no target keyword needed
A45: /legal/privacy-policy | B45: Legal | D45: =COUNTIFS(Keywords!$O:$O,A45,Keywords!$C:$C,"SEO") | E45: =COUNTIFS(Keywords!$O:$O,A45,Keywords!$C:$C,"AEO") | F45: P1 | G45: Not started | I45: Supporting page; no target keyword needed
A46: /legal/terms | B46: Legal | D46: =COUNTIFS(Keywords!$O:$O,A46,Keywords!$C:$C,"SEO") | E46: =COUNTIFS(Keywords!$O:$O,A46,Keywords!$C:$C,"AEO") | F46: P1 | G46: Not started | I46: Supporting page; no target keyword needed
A47: /blog/ai-coding-data-report | B47: Blog | C47: ai coding assistant statistics | D47: =COUNTIFS(Keywords!$O:$O,A47,Keywords!$C:$C,"SEO") | E47: =COUNTIFS(Keywords!$O:$O,A47,Keywords!$C:$C,"AEO") | F47: P3 | G47: Not started | I47: Original data report (Month 3)
A48: /blog/reduce-ai-coding-costs | B48: Blog | C48: how to reduce claude code cost | D48: =COUNTIFS(Keywords!$O:$O,A48,Keywords!$C:$C,"SEO") | E48: =COUNTIFS(Keywords!$O:$O,A48,Keywords!$C:$C,"AEO") | F48: P3 | G48: Not started | I48: New guide suggested by Google questions; link to /ai-cost-tracking
A49: /blog/tracking-ai-usage-ethically | B49: Blog | D49: =COUNTIFS(Keywords!$O:$O,A49,Keywords!$C:$C,"SEO") | E49: =COUNTIFS(Keywords!$O:$O,A49,Keywords!$C:$C,"AEO") | F49: P3 | G49: Not started | I49: Trust-building guide; supports /privacy
A50: /ai-coding-assistant-pricing | B50: Interactive tool | C50: ai coding assistant pricing | D50: =COUNTIFS(Keywords!$O:$O,A50,Keywords!$C:$C,"SEO") | E50: =COUNTIFS(Keywords!$O:$O,A50,Keywords!$C:$C,"AEO") | F50: P3 | G50: Not started | I50: Interactive pricing comparison, not a blog post; permanent URL outside /blog so it stays current. Google shows year-dated comparisons (DX, Stratas, FavTray) and vendor pages (JetBrains). Comparison table + team cost calculator + plan finder + FAQ. Show a 'Prices checked' date; one owner checks prices monthly; keep prices in one data source shared with /ai-cost-tracking and the ROI page

Sheet AEO Tracking
A1: Question | B1: Target Page | C1: ChatGPT | D1: Perplexity | E1: Claude | F1: Gemini | G1: Google AI Overview | H1: Times Mentioned (of 5) | I1: Competitors Cited | J1: Sources Cited | K1: Test Date
A2: How can I see how much each developer spends on AI coding tools? | B2: /ai-cost-tracking | H2: =COUNTIF(C2:G2,"Yes")
A3: How do I track Claude Code usage across my team? | B3: /integrations/claude-code | H3: =COUNTIF(C3:G3,"Yes")
A4: How do I know which developers are close to their Claude limit? | B4: /plan-headroom | H4: =COUNTIF(C4:G4,"Yes")
A5: What is the best tool to track AI coding assistant usage for a team? | B5: / | H5: =COUNTIF(C5:G5,"Yes")
A6: Is there a self-hosted tool to monitor AI coding tool usage? | B6: /self-hosted | H6: =COUNTIF(C6:G6,"Yes")
A7: How can I see all AI coding tools my team uses in one place? | B7: /integrations | H7: =COUNTIF(C7:G7,"Yes")
A8: How do I measure the ROI of AI coding tools? | B8: /blog/ai-coding-roi | H8: =COUNTIF(C8:G8,"Yes")
A9: How can I find shared or unused AI tool accounts? | B9: /shadow-ai | H9: =COUNTIF(C9:G9,"Yes")
A10: How do I find out which AI tools developers use without approval? | B10: /shadow-ai | H10: =COUNTIF(C10:G10,"Yes")
A11: How can managers spot struggling developers early without surveys? | B11: /engineering-intelligence | H11: =COUNTIF(C11:G11,"Yes")
A12: How do I know what my engineering team is working on right now? | B12: /engineering-intelligence | H12: =COUNTIF(C12:G12,"Yes")
A13: How do I stop my team solving the same bug twice? | B13: /blog/institutional-knowledge | H13: =COUNTIF(C13:G13,"Yes")
... A17: How do I track AI coding usage without monitoring keystrokes? | B17: /privacy | H17: =COUNTIF(C17:G17,"Yes")

Sheet Competitors
A1: Competitor | B1: Website | C1: Main Keywords They Rank For | D1: What They Do Well | E1: What They Miss | F1: Our Compare Page
A2: LinearB | B2: linearb.io | F2: /compare/linearb
A3: Jellyfish | B3: jellyfish.co | C3: measure roi of ai coding tools (#4); ai coding analytics (#2, 'best AI coding analytics platforms' list) | F3: /compare/jellyfish
A4: DX | B4: getdx.com | C4: measure roi of ai coding tools (#1, ROI calculator); ai coding assistant pricing (#1); developer experience metrics (#1, 'developer productivity metrics' blog); measure developer productivity with ai (#1, 'AI measurement hub') | F4: /compare/dx
A5: Swarmia | B5: swarmia.com | F5: /compare/swarmia
A6: GitHub Copilot Metrics | B6: github.com | F6: /compare/github-copilot-metrics
A7: Anthropic Console | B7: console.anthropic.com | F7: /compare/anthropic-console
A8: WakaTime | B8: wakatime.com | C8: ai coding analytics (#1, product homepage)
A9: Cortex | B9: cortex.io | C9: engineering intelligence platform (#1, definition + tools explainer); developer experience metrics (#2, blog)
A10: Uplevel | B10: uplevelteam.com | C10: engineering intelligence platform (#2, 'top platforms 2026' list); measure developer productivity with ai (#4, measurement guide)
A11: Port | B11: port.io | C11: developer experience metrics (#3, best practices + examples blog)
A12: Axify | B12: axify.io | C12: measure developer productivity with ai (#3, 'use AI for developer productivity' blog)

Sheet Keywords to Avoid
A1: Keyword | B1: Why Avoid
A2: employee monitoring software | B2: Wrong buyers; conflicts with 'historian, not critic'
A3: keystroke logging / screenshot monitoring | B3: Kite Pulse does not do this
A4: code quality scanner | B4: Not what Kite Pulse is
A5: llm observability | B5: That is for AI features inside a company's own product
A6: developer performance ranking | B6: Conflicts with the privacy message
A7: Trends / Cost & ROI / Ask Kite Pulse / Knowledge Base features | B7: Switched off in the current release; do not target until live
